C:\Users\geeta\PycharmProjects\LIC
C:\Users\geeta\PycharmProjects\LIC
C:\Users\geeta\PycharmProjects\LIC
C:\Users\geeta\PycharmProjects\LIC/uploads/
saving C:\Users\geeta\PycharmProjects\LIC/uploads/fire.png
C:\Users\geeta\PycharmProjects\LIC/uploads/
saving C:\Users\geeta\PycharmProjects\LIC/uploads/fire.png
C:\Users\geeta\PycharmProjects\LIC
C:\Users\geeta\PycharmProjects\LIC/uploads/
saving C:\Users\geeta\PycharmProjects\LIC/uploads/png_patch_of_land_by_paradise234-d5cd6qw.png
C:\Users\geeta\PycharmProjects\LIC
C:\Users\geeta\PycharmProjects\LIC/uploads/
saving C:\Users\geeta\PycharmProjects\LIC/uploads/bl_003783_a.jpg
saving C:\Users\geeta\PycharmProjects\LIC/uploads/1.jpg
Exception on /upl [POST]
Traceback (most recent call last):
  File "C:\Users\geeta\PycharmProjects\LIC\venv\lib\site-packages\flask\app.py", line 2292, in wsgi_app
    response = self.full_dispatch_request()
  File "C:\Users\geeta\PycharmProjects\LIC\venv\lib\site-packages\flask\app.py", line 1816, in full_dispatch_request
    return self.finalize_request(rv)
  File "C:\Users\geeta\PycharmProjects\LIC\venv\lib\site-packages\flask\app.py", line 1831, in finalize_request
    response = self.make_response(rv)
  File "C:\Users\geeta\PycharmProjects\LIC\venv\lib\site-packages\flask\app.py", line 1957, in make_response
    'The view function did not return a valid response. The'
TypeError: The view function did not return a valid response. The function either returned None or ended without a return statement.
C:\Users\geeta\PycharmProjects\LIC
C:\Users\geeta\PycharmProjects\LIC/uploads/
saving C:\Users\geeta\PycharmProjects\LIC/uploads/eid-collection-768x838.jpg
saving C:\Users\geeta\PycharmProjects\LIC/uploads/colorful_coffee_mugs_3d-t2.jpg
C:\Users\geeta\PycharmProjects\LIC
C:\Users\geeta\PycharmProjects\LIC/uploads/
saving C:\Users\geeta\PycharmProjects\LIC/uploads/bl_003783_a.jpg
saving C:\Users\geeta\PycharmProjects\LIC/uploads/1.jpg
C:\Users\geeta\PycharmProjects\LIC
C:\Users\geeta\PycharmProjects\LIC/uploads/
saving C:\Users\geeta\PycharmProjects\LIC/uploads/bl_003783_a.jpg
saving C:\Users\geeta\PycharmProjects\LIC/uploads/1.jpg
C:\Users\geeta\PycharmProjects\LIC
C:\Users\geeta\PycharmProjects\LIC/uploads/
saving C:\Users\geeta\PycharmProjects\LIC/uploads/desert_sky-t2.jpg
saving C:\Users\geeta\PycharmProjects\LIC/uploads/dreamstime_xxl_102634588.jpg
C:\Users\geeta\PycharmProjects\LIC
C:\Users\geeta\PycharmProjects\LIC/uploads/
C:\Users\geeta\PycharmProjects\LIC
C:\Users\geeta\PycharmProjects\LIC/uploads/
C:\Users\geeta\PycharmProjects\LIC
C:\Users\geeta\PycharmProjects\LIC/uploads/
saving C:\Users\geeta\PycharmProjects\LIC/uploads/eid-collection-768x838.jpg
Exception on /edit [GET]
Traceback (most recent call last):
  File "C:\Users\geeta\PycharmProjects\LIC\venv\lib\site-packages\flask\app.py", line 2292, in wsgi_app
    response = self.full_dispatch_request()
  File "C:\Users\geeta\PycharmProjects\LIC\venv\lib\site-packages\flask\app.py", line 1815, in full_dispatch_request
    rv = self.handle_user_exception(e)
  File "C:\Users\geeta\PycharmProjects\LIC\venv\lib\site-packages\flask\app.py", line 1718, in handle_user_exception
    reraise(exc_type, exc_value, tb)
  File "C:\Users\geeta\PycharmProjects\LIC\venv\lib\site-packages\flask\app.py", line 1813, in full_dispatch_request
    rv = self.dispatch_request()
  File "C:\Users\geeta\PycharmProjects\LIC\venv\lib\site-packages\flask\app.py", line 1799, in dispatch_request
    return self.view_functions[rule.endpoint](**req.view_args)
  File "C:\Users\geeta\PycharmProjects\LIC\app.py", line 150, in edit
    return "hi "+request.query_string["id"]
TypeError: string indices must be integers, not str
Exception on /edit [GET]
Traceback (most recent call last):
  File "C:\Users\geeta\PycharmProjects\LIC\venv\lib\site-packages\flask\app.py", line 2292, in wsgi_app
    response = self.full_dispatch_request()
  File "C:\Users\geeta\PycharmProjects\LIC\venv\lib\site-packages\flask\app.py", line 1815, in full_dispatch_request
    rv = self.handle_user_exception(e)
  File "C:\Users\geeta\PycharmProjects\LIC\venv\lib\site-packages\flask\app.py", line 1718, in handle_user_exception
    reraise(exc_type, exc_value, tb)
  File "C:\Users\geeta\PycharmProjects\LIC\venv\lib\site-packages\flask\app.py", line 1813, in full_dispatch_request
    rv = self.dispatch_request()
  File "C:\Users\geeta\PycharmProjects\LIC\venv\lib\site-packages\flask\app.py", line 1799, in dispatch_request
    return self.view_functions[rule.endpoint](**req.view_args)
  File "C:\Users\geeta\PycharmProjects\LIC\app.py", line 150, in edit
    return "hi "+str(request.query_string["id"])
TypeError: string indices must be integers, not str
Exception on /edit [GET]
Traceback (most recent call last):
  File "C:\Users\geeta\PycharmProjects\LIC\venv\lib\site-packages\flask\app.py", line 2292, in wsgi_app
    response = self.full_dispatch_request()
  File "C:\Users\geeta\PycharmProjects\LIC\venv\lib\site-packages\flask\app.py", line 1815, in full_dispatch_request
    rv = self.handle_user_exception(e)
  File "C:\Users\geeta\PycharmProjects\LIC\venv\lib\site-packages\flask\app.py", line 1718, in handle_user_exception
    reraise(exc_type, exc_value, tb)
  File "C:\Users\geeta\PycharmProjects\LIC\venv\lib\site-packages\flask\app.py", line 1813, in full_dispatch_request
    rv = self.dispatch_request()
  File "C:\Users\geeta\PycharmProjects\LIC\venv\lib\site-packages\flask\app.py", line 1799, in dispatch_request
    return self.view_functions[rule.endpoint](**req.view_args)
  File "C:\Users\geeta\PycharmProjects\LIC\app.py", line 150, in edit
    return request.query_string["id"]
TypeError: string indices must be integers, not str
Exception on /edit [GET]
Traceback (most recent call last):
  File "C:\Users\geeta\PycharmProjects\LIC\venv\lib\site-packages\flask\app.py", line 2292, in wsgi_app
    response = self.full_dispatch_request()
  File "C:\Users\geeta\PycharmProjects\LIC\venv\lib\site-packages\flask\app.py", line 1815, in full_dispatch_request
    rv = self.handle_user_exception(e)
  File "C:\Users\geeta\PycharmProjects\LIC\venv\lib\site-packages\flask\app.py", line 1718, in handle_user_exception
    reraise(exc_type, exc_value, tb)
  File "C:\Users\geeta\PycharmProjects\LIC\venv\lib\site-packages\flask\app.py", line 1813, in full_dispatch_request
    rv = self.dispatch_request()
  File "C:\Users\geeta\PycharmProjects\LIC\venv\lib\site-packages\flask\app.py", line 1799, in dispatch_request
    return self.view_functions[rule.endpoint](**req.view_args)
  File "C:\Users\geeta\PycharmProjects\LIC\app.py", line 149, in edit
    print(request.query_string["id"])
TypeError: string indices must be integers, not str
Exception on /edit [GET]
Traceback (most recent call last):
  File "C:\Users\geeta\PycharmProjects\LIC\venv\lib\site-packages\flask\app.py", line 2292, in wsgi_app
    response = self.full_dispatch_request()
  File "C:\Users\geeta\PycharmProjects\LIC\venv\lib\site-packages\flask\app.py", line 1815, in full_dispatch_request
    rv = self.handle_user_exception(e)
  File "C:\Users\geeta\PycharmProjects\LIC\venv\lib\site-packages\flask\app.py", line 1718, in handle_user_exception
    reraise(exc_type, exc_value, tb)
  File "C:\Users\geeta\PycharmProjects\LIC\venv\lib\site-packages\flask\app.py", line 1813, in full_dispatch_request
    rv = self.dispatch_request()
  File "C:\Users\geeta\PycharmProjects\LIC\venv\lib\site-packages\flask\app.py", line 1799, in dispatch_request
    return self.view_functions[rule.endpoint](**req.view_args)
  File "C:\Users\geeta\PycharmProjects\LIC\app.py", line 149, in edit
    print(int(request.query_string["id"]))
TypeError: string indices must be integers, not str
Exception on / [GET]
Traceback (most recent call last):
  File "C:\Python37-32\lib\site-packages\mysql\connector\network.py", line 509, in open_connection
    self.sock.connect(sockaddr)
ConnectionRefusedError: [WinError 10061] No connection could be made because the target machine actively refused it

During handling of the above exception, another exception occurred:

Traceback (most recent call last):
  File "C:\Python37-32\lib\site-packages\flask\app.py", line 2292, in wsgi_app
    response = self.full_dispatch_request()
  File "C:\Python37-32\lib\site-packages\flask\app.py", line 1815, in full_dispatch_request
    rv = self.handle_user_exception(e)
  File "C:\Python37-32\lib\site-packages\flask\app.py", line 1718, in handle_user_exception
    reraise(exc_type, exc_value, tb)
  File "C:\Python37-32\lib\site-packages\flask\_compat.py", line 35, in reraise
    raise value
  File "C:\Python37-32\lib\site-packages\flask\app.py", line 1813, in full_dispatch_request
    rv = self.dispatch_request()
  File "C:\Python37-32\lib\site-packages\flask\app.py", line 1799, in dispatch_request
    return self.view_functions[rule.endpoint](**req.view_args)
  File "C:/Users/Dell/PycharmProjects/LIC/LIC/app.py", line 120, in display_deals
    conn = mysql.connector.connect(host="localhost", user="root", password="", db="LIC")
  File "C:\Python37-32\lib\site-packages\mysql\connector\__init__.py", line 179, in connect
    return MySQLConnection(*args, **kwargs)
  File "C:\Python37-32\lib\site-packages\mysql\connector\connection.py", line 95, in __init__
    self.connect(**kwargs)
  File "C:\Python37-32\lib\site-packages\mysql\connector\abstracts.py", line 716, in connect
    self._open_connection()
  File "C:\Python37-32\lib\site-packages\mysql\connector\connection.py", line 206, in _open_connection
    self._socket.open_connection()
  File "C:\Python37-32\lib\site-packages\mysql\connector\network.py", line 512, in open_connection
    errno=2003, values=(self.get_address(), _strioerror(err)))
mysql.connector.errors.InterfaceError: 2003: Can't connect to MySQL server on 'localhost:3306' (10061 No connection could be made because the target machine actively refused it)
